Workbook

Sheet Rules
A1: today | B1: 46310
A2: idle_days | B2: 7
A3: customs_days
A5: Edit the yellow cells. Leave customs_days empty to switch the customs rule off.

Sheet Summary
A1: Carrier | B1: Stuck | C1: Total | D1: Share
A2: AndesCargo | B2: =COUNTIFS(Data!$C$2:$C$1001,A2,Data!$I$2:$I$1001,"?*") | C2: =COUNTIF(Data!$C$2:$C$1001,A2) | D2: =IF(C2=0,0,B2/C2)
A3: SwiftParcel | B3: =COUNTIFS(Data!$C$2:$C$1001,A3,Data!$I$2:$I$1001,"?*") | C3: =COUNTIF(Data!$C$2:$C$1001,A3) | D3: =IF(C3=0,0,B3/C3)
A4: PostLink | B4: =COUNTIFS(Data!$C$2:$C$1001,A4,Data!$I$2:$I$1001,"?*") | C4: =COUNTIF(Data!$C$2:$C$1001,A4) | D4: =IF(C4=0,0,B4/C4)
A5: Total | B5: =SUM(B2:B4) | C5: =SUM(C2:C4)
A7: today: | B7: =Rules!B1
A8: Stuck list: Data sheet, filter column I not empty, sort by column J.

Sheet Data
A1: Order | B1: Country | C1: Carrier | D1: Tracking | E1: Ship date | F1: Last event | G1: Last event date | H1: days idle | I1: reason | J1: priority
A2: 100001 | B2: Канада | C2: PostLink | D2: PL47483092 | E2: 46285 | F2: Delivered | G2: 46290 | H2: =IF(G2="","",Rules!$B$1-G2) | I2: =IF(F2="Address issue","address issue",IF(OR(F2="Delivered",F2="Returned to sender",G2=""),"",IF(AND(Rules!$B$3<>"",F2="Held at customs",H2>=Rules!$B$3),"customs >= "&Rules!$B$3&" days",IF(H2>=Rules!$B$2,"idle >= "&Rules!$B$2&" days","")))) | J2: =IF(I2="","",IF(F2="Address issue",0,COUNTIF($I$2:$I$1001,"address issue"))+COUNTIFS($I$2:$I$1001,"?*",$F$2:$F$1001,IF(F2="Address issue","Address issue","<>Address issue"),$H$2:$H$1001,">"&H2)+1)
A3: 100002 | B3: Канада | C3: PostLink | D3: PL94699845 | E3: 46301 | F3: In transit | G3: 46307 | H3: =IF(G3="","",Rules!$B$1-G3) | I3: =IF(F3="Address issue","address issue",IF(OR(F3="Delivered",F3="Returned to sender",G3=""),"",IF(AND(Rules!$B$3<>"",F3="Held at customs",H3>=Rules!$B$3),"customs >= "&Rules!$B$3&" days",IF(H3>=Rules!$B$2,"idle >= "&Rules!$B$2&" days","")))) | J3: =IF(I3="","",IF(F3="Address issue",0,COUNTIF($I$2:$I$1001,"address issue"))+COUNTIFS($I$2:$I$1001,"?*",$F$2:$F$1001,IF(F3="Address issue","Address issue","<>Address issue"),$H$2:$H$1001,">"&H3)+1)
A4: 100003 | B4: Мексика | C4: AndesCargo | D4: AC42940501 | E4: 46284 | F4: Delivered | G4: 46290 | H4: =IF(G4="","",Rules!$B$1-G4) | I4: =IF(F4="Address issue","address issue",IF(OR(F4="Delivered",F4="Returned to sender",G4=""),"",IF(AND(Rules!$B$3<>"",F4="Held at customs",H4>=Rules!$B$3),"customs >= "&Rules!$B$3&" days",IF(H4>=Rules!$B$2,"idle >= "&Rules!$B$2&" days","")))) | J4: =IF(I4="","",IF(F4="Address issue",0,COUNTIF($I$2:$I$1001,"address issue"))+COUNTIFS($I$2:$I$1001,"?*",$F$2:$F$1001,IF(F4="Address issue","Address issue","<>Address issue"),$H$2:$H$1001,">"&H4)+1)
A5: 100004 | B5: Бразилія | C5: SwiftParcel | D5: SP6865562 | E5: 46298 | F5: Address issue | G5: 46301 | H5: =IF(G5="","",Rules!$B$1-G5) | I5: =IF(F5="Address issue","address issue",IF(OR(F5="Delivered",F5="Returned to sender",G5=""),"",IF(AND(Rules!$B$3<>"",F5="Held at customs",H5>=Rules!$B$3),"customs >= "&Rules!$B$3&" days",IF(H5>=Rules!$B$2,"idle >= "&Rules!$B$2&" days","")))) | J5: =IF(I5="","",IF(F5="Address issue",0,COUNTIF($I$2:$I$1001,"address issue"))+COUNTIFS($I$2:$I$1001,"?*",$F$2:$F$1001,IF(F5="Address issue","Address issue","<>Address issue"),$H$2:$H$1001,">"&H5)+1)
A6: 100005 | B6: Мексика | C6: AndesCargo | D6: AC83407141 | E6: 46304 | F6: In transit | G6: 46310 | H6: =IF(G6="","",Rules!$B$1-G6) | I6: =IF(F6="Address issue","address issue",IF(OR(F6="Delivered",F6="Returned to sender",G6=""),"",IF(AND(Rules!$B$3<>"",F6="Held at customs",H6>=Rules!$B$3),"customs >= "&Rules!$B$3&" days",IF(H6>=Rules!$B$2,"idle >= "&Rules!$B$2&" days","")))) | J6: =IF(I6="","",IF(F6="Address issue",0,COUNTIF($I$2:$I$1001,"address issue"))+COUNTIFS($I$2:$I$1001,"?*",$F$2:$F$1001,IF(F6="Address issue","Address issue","<>Address issue"),$H$2:$H$1001,">"&H6)+1)
A7: 100006 | B7: Бразилія | C7: SwiftParcel | D7: SP8115549 | E7: 46271 | F7: Delivered | G7: 46282 | H7: =IF(G7="","",Rules!$B$1-G7) | I7: =IF(F7="Address issue","address issue",IF(OR(F7="Delivered",F7="Returned to sender",G7=""),"",IF(AND(Rules!$B$3<>"",F7="Held at customs",H7>=Rules!$B$3),"customs >= "&Rules!$B$3&" days",IF(H7>=Rules!$B$2,"idle >= "&Rules!$B$2&" days","")))) | J7: =IF(I7="","",IF(F7="Address issue",0,COUNTIF($I$2:$I$1001,"address issue"))+COUNTIFS($I$2:$I$1001,"?*",$F$2:$F$1001,IF(F7="Address issue","Address issue","<>Address issue"),$H$2:$H$1001,">"&H7)+1)
A8: 100007 | B8: Канада | C8: PostLink | D8: PL19701823 | E8: 46290 | F8: Delivered | G8: 46302 | H8: =IF(G8="","",Rules!$B$1-G8) | I8: =IF(F8="Address issue","address issue",IF(OR(F8="Delivered",F8="Returned to sender",G8=""),"",IF(AND(Rules!$B$3<>"",F8="Held at customs",H8>=Rules!$B$3),"customs >= "&Rules!$B$3&" days",IF(H8>=Rules!$B$2,"idle >= "&Rules!$B$2&" days","")))) | J8: =IF(I8="","",IF(F8="Address issue",0,COUNTIF($I$2:$I$1001,"address issue"))+COUNTIFS($I$2:$I$1001,"?*",$F$2:$F$1001,IF(F8="Address issue","Address issue","<>Address issue"),$H$2:$H$1001,">"&H8)+1)
A9: 100008 | B9: Бразилія | C9: SwiftParcel | D9: SP1984975 | E9: 46306 | F9: Label created | G9: 46306 | H9: =IF(G9="","",Rules!$B$1-G9) | I9: =IF(F9="Address issue","address issue",IF(OR(F9="Delivered",F9="Returned to sender",G9=""),"",IF(AND(Rules!$B$3<>"",F9="Held at customs",H9>=Rules!$B$3),"customs >= "&Rules!$B$3&" days",IF(H9>=Rules!$B$2,"idle >= "&Rules!$B$2&" days","")))) | J9: =IF(I9="","",IF(F9="Address issue",0,COUNTIF($I$2:$I$1001,"address issue"))+COUNTIFS($I$2:$I$1001,"?*",$F$2:$F$1001,IF(F9="Address issue","Address issue","<>Address issue"),$H$2:$H$1001,">"&H9)+1)
A10: 100009 | B10: Бразилія | C10: AndesCargo | D10: AC17088206 | E10: 46295 | F10: Held at customs | G10: 46296 | H10: =IF(G10="","",Rules!$B$1-G10) | I10: =IF(F10="Address issue","address issue",IF(OR(F10="Delivered",F10="Returned to sender",G10=""),"",IF(AND(Rules!$B$3<>"",F10="Held at customs",H10>=Rules!$B$3),"customs >= "&Rules!$B$3&" days",IF(H10>=Rules!$B$2,"idle >= "&Rules!$B$2&" days","")))) | J10: =IF(I10="","",IF(F10="Address issue",0,COUNTIF($I$2:$I$1001,"address issue"))+COUNTIFS($I$2:$I$1001,"?*",$F$2:$F$1001,IF(F10="Address issue","Address issue","<>Address issue"),$H$2:$H$1001,">"&H10)+1)
A11: 100010 | B11: Канада | C11: PostLink | D11: PL23325420 | E11: 46300 | F11: Out for delivery | G11: 46306 | H11: =IF(G11="","",Rules!$B$1-G11) | I11: =IF(F11="Address issue","address issue",IF(OR(F11="Delivered",F11="Returned to sender",G11=""),"",IF(AND(Rules!$B$3<>"",F11="Held at customs",H11>=Rules!$B$3),"customs >= "&Rules!$B$3&" days",IF(H11>=Rules!$B$2,"idle >= "&Rules!$B$2&" days","")))) | J11: =IF(I11="","",IF(F11="Address issue",0,COUNTIF($I$2:$I$1001,"address issue"))+COUNTIFS($I$2:$I$1001,"?*",$F$2:$F$1001,IF(F11="Address issue","Address issue","<>Address issue"),$H$2:$H$1001,">"&H11)+1)
A12: 100011 | B12: Бразилія | C12: AndesCargo | D12: AC69505399 | E12: 46290 | F12: Delivered | G12: 46293 | H12: =IF(G12="","",Rules!$B$1-G12) | I12: =IF(F12="Address issue","address issue",IF(OR(F12="Delivered",F12="Returned to sender",G12=""),"",IF(AND(Rules!$B$3<>"",F12="Held at customs",H12>=Rules!$B$3),"customs >= "&Rules!$B$3&" days",IF(H12>=Rules!$B$2,"idle >= "&Rules!$B$2&" days","")))) | J12: =IF(I12="","",IF(F12="Address issue",0,COUNTIF($I$2:$I$1001,"address issue"))+COUNTIFS($I$2:$I$1001,"?*",$F$2:$F$1001,IF(F12="Address issue","Address issue","<>Address issue"),$H$2:$H$1001,">"&H12)+1)
A13: 100012 | B13: Бразилія | C13: SwiftParcel | D13: SP1413050 | E13: 46289 | F13: Held at customs | G13: 46297 | H13: =IF(G13="","",Rules!$B$1-G13) | I13: =IF(F13="Address issue","address issue",IF(OR(F13="Delivered",F13="Returned to sender",G13=""),"",IF(AND(Rules!$B$3<>"",F13="Held at customs",H13>=Rules!$B$3),"customs >= "&Rules!$B$3&" days",IF(H13>=Rules!$B$2,"idle >= "&Rules!$B$2&" days","")))) | J13: =IF(I13="","",IF(F13="Address issue",0,COUNTIF($I$2:$I$1001,"address issue"))+COUNTIFS($I$2:$I$1001,"?*",$F$2:$F$1001,IF(F13="Address issue","Address issue","<>Address issue"),$H$2:$H$1001,">"&H13)+1)
... A53: 100052 | B53: Мексика | C53: AndesCargo | D53: AC59360709 | E53: 46298 | F53: Delivered | G53: 46305 | H53: =IF(G53="","",Rules!$B$1-G53) | I53: =IF(F53="Address issue","address issue",IF(OR(F53="Delivered",F53="Returned to sender",G53=""),"",IF(AND(Rules!$B$3<>"",F53="Held at customs",H53>=Rules!$B$3),"customs >= "&Rules!$B$3&" days",IF(H53>=Rules!$B$2,"idle >= "&Rules!$B$2&" days","")))) | J53: =IF(I53="","",IF(F53="Address issue",0,COUNTIF($I$2:$I$1001,"address issue"))+COUNTIFS($I$2:$I$1001,"?*",$F$2:$F$1001,IF(F53="Address issue","Address issue","<>Address issue"),$H$2:$H$1001,">"&H53)+1)
A54: 100053 | B54: Бразилія | C54: AndesCargo | E54: 46292 | H54: =IF(G54="","",Rules!$B$1-G54) | I54: =IF(F54="Address issue","address issue",IF(OR(F54="Delivered",F54="Returned to sender",G54=""),"",IF(AND(Rules!$B$3<>"",F54="Held at customs",H54>=Rules!$B$3),"customs >= "&Rules!$B$3&" days",IF(H54>=Rules!$B$2,"idle >= "&Rules!$B$2&" days","")))) | J54: =IF(I54="","",IF(F54="Address issue",0,COUNTIF($I$2:$I$1001,"address issue"))+COUNTIFS($I$2:$I$1001,"?*",$F$2:$F$1001,IF(F54="Address issue","Address issue","<>Address issue"),$H$2:$H$1001,">"&H54)+1)
A55: 100054 | B55: Бразилія | C55: SwiftParcel | D55: SP6635524 | E55: 46293 | F55: Delivered | G55: 46302 | H55: =IF(G55="","",Rules!$B$1-G55) | I55: =IF(F55="Address issue","address issue",IF(OR(F55="Delivered",F55="Returned to sender",G55=""),"",IF(AND(Rules!$B$3<>"",F55="Held at customs",H55>=Rules!$B$3),"customs >= "&Rules!$B$3&" days",IF(H55>=Rules!$B$2,"idle >= "&Rules!$B$2&" days","")))) | J55: =IF(I55="","",IF(F55="Address issue",0,COUNTIF($I$2:$I$1001,"address issue"))+COUNTIFS($I$2:$I$1001,"?*",$F$2:$F$1001,IF(F55="Address issue","Address issue","<>Address issue"),$H$2:$H$1001,">"&H55)+1)
A56: 100055 | B56: Мексика | C56: AndesCargo | D56: AC63942720 | E56: 46278 | F56: Delivered | G56: 46288 | H56: =IF(G56="","",Rules!$B$1-G56) | I56: =IF(F56="Address issue","address issue",IF(OR(F56="Delivered",F56="Returned to sender",G56=""),"",IF(AND(Rules!$B$3<>"",F56="Held at customs",H56>=Rules!$B$3),"customs >= "&Rules!$B$3&" days",IF(H56>=Rules!$B$2,"idle >= "&Rules!$B$2&" days","")))) | J56: =IF(I56="","",IF(F56="Address issue",0,COUNTIF($I$2:$I$1001,"address issue"))+COUNTIFS($I$2:$I$1001,"?*",$F$2:$F$1001,IF(F56="Address issue","Address issue","<>Address issue"),$H$2:$H$1001,">"&H56)+1)
A57: 100056 | B57: Мексика | C57: AndesCargo | D57: AC30079420 | E57: 46300 | F57: Delivered | G57: 46306 | H57: =IF(G57="","",Rules!$B$1-G57) | I57: =IF(F57="Address issue","address issue",IF(OR(F57="Delivered",F57="Returned to sender",G57=""),"",IF(AND(Rules!$B$3<>"",F57="Held at customs",H57>=Rules!$B$3),"customs >= "&Rules!$B$3&" days",IF(H57>=Rules!$B$2,"idle >= "&Rules!$B$2&" days","")))) | J57: =IF(I57="","",IF(F57="Address issue",0,COUNTIF($I$2:$I$1001,"address issue"))+COUNTIFS($I$2:$I$1001,"?*",$F$2:$F$1001,IF(F57="Address issue","Address issue","<>Address issue"),$H$2:$H$1001,">"&H57)+1)
A58: 100057 | B58: Мексика | C58: AndesCargo | D58: AC74395928 | E58: 46297 | F58: Delivered | G58: 46302 | H58: =IF(G58="","",Rules!$B$1-G58) | I58: =IF(F58="Address issue","address issue",IF(OR(F58="Delivered",F58="Returned to sender",G58=""),"",IF(AND(Rules!$B$3<>"",F58="Held at customs",H58>=Rules!$B$3),"customs >= "&Rules!$B$3&" days",IF(H58>=Rules!$B$2,"idle >= "&Rules!$B$2&" days","")))) | J58: =IF(I58="","",IF(F58="Address issue",0,COUNTIF($I$2:$I$1001,"address issue"))+COUNTIFS($I$2:$I$1001,"?*",$F$2:$F$1001,IF(F58="Address issue","Address issue","<>Address issue"),$H$2:$H$1001,">"&H58)+1)
A59: 100058 | B59: Мексика | C59: SwiftParcel | D59: SP1050264 | E59: 46285 | F59: Delivered | G59: 46290 | H59: =IF(G59="","",Rules!$B$1-G59) | I59: =IF(F59="Address issue","address issue",IF(OR(F59="Delivered",F59="Returned to sender",G59=""),"",IF(AND(Rules!$B$3<>"",F59="Held at customs",H59>=Rules!$B$3),"customs >= "&Rules!$B$3&" days",IF(H59>=Rules!$B$2,"idle >= "&Rules!$B$2&" days","")))) | J59: =IF(I59="","",IF(F59="Address issue",0,COUNTIF($I$2:$I$1001,"address issue"))+COUNTIFS($I$2:$I$1001,"?*",$F$2:$F$1001,IF(F59="Address issue","Address issue","<>Address issue"),$H$2:$H$1001,">"&H59)+1)
A60: 100059 | B60: Бразилія | C60: SwiftParcel | D60: SP9967190 | E60: 46302 | F60: In transit | G60: 46306 | H60: =IF(G60="","",Rules!$B$1-G60) | I60: =IF(F60="Address issue","address issue",IF(OR(F60="Delivered",F60="Returned to sender",G60=""),"",IF(AND(Rules!$B$3<>"",F60="Held at customs",H60>=Rules!$B$3),"customs >= "&Rules!$B$3&" days",IF(H60>=Rules!$B$2,"idle >= "&Rules!$B$2&" days","")))) | J60: =IF(I60="","",IF(F60="Address issue",0,COUNTIF($I$2:$I$1001,"address issue"))+COUNTIFS($I$2:$I$1001,"?*",$F$2:$F$1001,IF(F60="Address issue","Address issue","<>Address issue"),$H$2:$H$1001,">"&H60)+1)
A61: 100060 | B61: Канада | C61: PostLink | D61: PL84200104 | E61: 46286 | F61: Delivered | G61: 46290 | H61: =IF(G61="","",Rules!$B$1-G61) | I61: =IF(F61="Address issue","address issue",IF(OR(F61="Delivered",F61="Returned to sender",G61=""),"",IF(AND(Rules!$B$3<>"",F61="Held at customs",H61>=Rules!$B$3),"customs >= "&Rules!$B$3&" days",IF(H61>=Rules!$B$2,"idle >= "&Rules!$B$2&" days","")))) | J61: =IF(I61="","",IF(F61="Address issue",0,COUNTIF($I$2:$I$1001,"address issue"))+COUNTIFS($I$2:$I$1001,"?*",$F$2:$F$1001,IF(F61="Address issue","Address issue","<>Address issue"),$H$2:$H$1001,">"&H61)+1)
A62: 100061 | B62: Бразилія | C62: SwiftParcel | D62: SP5451570 | E62: 46296 | F62: Held at customs | G62: 46298 | H62: =IF(G62="","",Rules!$B$1-G62) | I62: =IF(F62="Address issue","address issue",IF(OR(F62="Delivered",F62="Returned to sender",G62=""),"",IF(AND(Rules!$B$3<>"",F62="Held at customs",H62>=Rules!$B$3),"customs >= "&Rules!$B$3&" days",IF(H62>=Rules!$B$2,"idle >= "&Rules!$B$2&" days","")))) | J62: =IF(I62="","",IF(F62="Address issue",0,COUNTIF($I$2:$I$1001,"address issue"))+COUNTIFS($I$2:$I$1001,"?*",$F$2:$F$1001,IF(F62="Address issue","Address issue","<>Address issue"),$H$2:$H$1001,">"&H62)+1)
A63: 100062 | B63: Мексика | C63: AndesCargo | D63: AC38752097 | E63: 46282 | F63: Delivered | G63: 46285 | H63: =IF(G63="","",Rules!$B$1-G63) | I63: =IF(F63="Address issue","address issue",IF(OR(F63="Delivered",F63="Returned to sender",G63=""),"",IF(AND(Rules!$B$3<>"",F63="Held at customs",H63>=Rules!$B$3),"customs >= "&Rules!$B$3&" days",IF(H63>=Rules!$B$2,"idle >= "&Rules!$B$2&" days","")))) | J63: =IF(I63="","",IF(F63="Address issue",0,COUNTIF($I$2:$I$1001,"address issue"))+COUNTIFS($I$2:$I$1001,"?*",$F$2:$F$1001,IF(F63="Address issue","Address issue","<>Address issue"),$H$2:$H$1001,">"&H63)+1)
A64: 100063 | B64: Мексика | C64: AndesCargo | D64: AC99751612 | E64: 46294 | F64: Delivered | G64: 46298 | H64: =IF(G64="","",Rules!$B$1-G64) | I64: =IF(F64="Address issue","address issue",IF(OR(F64="Delivered",F64="Returned to sender",G64=""),"",IF(AND(Rules!$B$3<>"",F64="Held at customs",H64>=Rules!$B$3),"customs >= "&Rules!$B$3&" days",IF(H64>=Rules!$B$2,"idle >= "&Rules!$B$2&" days","")))) | J64: =IF(I64="","",IF(F64="Address issue",0,COUNTIF($I$2:$I$1001,"address issue"))+COUNTIFS($I$2:$I$1001,"?*",$F$2:$F$1001,IF(F64="Address issue","Address issue","<>Address issue"),$H$2:$H$1001,">"&H64)+1)
A65: 100064 | B65: Бразилія | C65: SwiftParcel | D65: SP9039487 | E65: 46305 | F65: In transit | G65: 46307 | H65: =IF(G65="","",Rules!$B$1-G65) | I65: =IF(F65="Address issue","address issue",IF(OR(F65="Delivered",F65="Returned to sender",G65=""),"",IF(AND(Rules!$B$3<>"",F65="Held at customs",H65>=Rules!$B$3),"customs >= "&Rules!$B$3&" days",IF(H65>=Rules!$B$2,"idle >= "&Rules!$B$2&" days","")))) | J65: =IF(I65="","",IF(F65="Address issue",0,COUNTIF($I$2:$I$1001,"address issue"))+COUNTIFS($I$2:$I$1001,"?*",$F$2:$F$1001,IF(F65="Address issue","Address issue","<>Address issue"),$H$2:$H$1001,">"&H65)+1)
A66: 100065 | B66: Мексика | C66: AndesCargo | D66: AC32430926 | E66: 46276 | F66: Delivered | G66: 46282 | H66: =IF(G66="","",Rules!$B$1-G66) | I66: =IF(F66="Address issue","address issue",IF(OR(F66="Delivered",F66="Returned to sender",G66=""),"",IF(AND(Rules!$B$3<>"",F66="Held at customs",H66>=Rules!$B$3),"customs >= "&Rules!$B$3&" days",IF(H66>=Rules!$B$2,"idle >= "&Rules!$B$2&" days","")))) | J66: =IF(I66="","",IF(F66="Address issue",0,COUNTIF($I$2:$I$1001,"address issue"))+COUNTIFS($I$2:$I$1001,"?*",$F$2:$F$1001,IF(F66="Address issue","Address issue","<>Address issue"),$H$2:$H$1001,">"&H66)+1)
... A354: 100353 | B354: Мексика | C354: AndesCargo | D354: AC22275625 | E354: 46293 | F354: In transit | G354: 46297 | H354: =IF(G354="","",Rules!$B$1-G354) | I354: =IF(F354="Address issue","address issue",IF(OR(F354="Delivered",F354="Returned to sender",G354=""),"",IF(AND(Rules!$B$3<>"",F354="Held at customs",H354>=Rules!$B$3),"customs >= "&Rules!$B$3&" days",IF(H354>=Rules!$B$2,"idle >= "&Rules!$B$2&" days","")))) | J354: =IF(I354="","",IF(F354="Address issue",0,COUNTIF($I$2:$I$1001,"address issue"))+COUNTIFS($I$2:$I$1001,"?*",$F$2:$F$1001,IF(F354="Address issue","Address issue","<>Address issue"),$H$2:$H$1001,">"&H354)+1)
A355: 100354 | B355: Мексика | C355: AndesCargo | E355: 46288 | H355: =IF(G355="","",Rules!$B$1-G355) | I355: =IF(F355="Address issue","address issue",IF(OR(F355="Delivered",F355="Returned to sender",G355=""),"",IF(AND(Rules!$B$3<>"",F355="Held at customs",H355>=Rules!$B$3),"customs >= "&Rules!$B$3&" days",IF(H355>=Rules!$B$2,"idle >= "&Rules!$B$2&" days","")))) | J355: =IF(I355="","",IF(F355="Address issue",0,COUNTIF($I$2:$I$1001,"address issue"))+COUNTIFS($I$2:$I$1001,"?*",$F$2:$F$1001,IF(F355="Address issue","Address issue","<>Address issue"),$H$2:$H$1001,">"&H355)+1)
A356: 100355 | B356: Бразилія | C356: SwiftParcel | D356: SP8346516 | E356: 46286 | F356: In transit | G356: 46294 | H356: =IF(G356="","",Rules!$B$1-G356) | I356: =IF(F356="Address issue","address issue",IF(OR(F356="Delivered",F356="Returned to sender",G356=""),"",IF(AND(Rules!$B$3<>"",F356="Held at customs",H356>=Rules!$B$3),"customs >= "&Rules!$B$3&" days",IF(H356>=Rules!$B$2,"idle >= "&Rules!$B$2&" days","")))) | J356: =IF(I356="","",IF(F356="Address issue",0,COUNTIF($I$2:$I$1001,"address issue"))+COUNTIFS($I$2:$I$1001,"?*",$F$2:$F$1001,IF(F356="Address issue","Address issue","<>Address issue"),$H$2:$H$1001,">"&H356)+1)
A357: 100356 | B357: Мексика | C357: AndesCargo | D357: AC74117143 | E357: 46290 | F357: Held at customs | G357: 46296 | H357: =IF(G357="","",Rules!$B$1-G357) | I357: =IF(F357="Address issue","address issue",IF(OR(F357="Delivered",F357="Returned to sender",G357=""),"",IF(AND(Rules!$B$3<>"",F357="Held at customs",H357>=Rules!$B$3),"customs >= "&Rules!$B$3&" days",IF(H357>=Rules!$B$2,"idle >= "&Rules!$B$2&" days","")))) | J357: =IF(I357="","",IF(F357="Address issue",0,COUNTIF($I$2:$I$1001,"address issue"))+COUNTIFS($I$2:$I$1001,"?*",$F$2:$F$1001,IF(F357="Address issue","Address issue","<>Address issue"),$H$2:$H$1001,">"&H357)+1)
A358: 100357 | B358: Канада | C358: PostLink | D358: PL68783095 | E358: 46289 | F358: Delivered | G358: 46294 | H358: =IF(G358="","",Rules!$B$1-G358) | I358: =IF(F358="Address issue","address issue",IF(OR(F358="Delivered",F358="Returned to sender",G358=""),"",IF(AND(Rules!$B$3<>"",F358="Held at customs",H358>=Rules!$B$3),"customs >= "&Rules!$B$3&" days",IF(H358>=Rules!$B$2,"idle >= "&Rules!$B$2&" days","")))) | J358: =IF(I358="","",IF(F358="Address issue",0,COUNTIF($I$2:$I$1001,"address issue"))+COUNTIFS($I$2:$I$1001,"?*",$F$2:$F$1001,IF(F358="Address issue","Address issue","<>Address issue"),$H$2:$H$1001,">"&H358)+1)
A359: 100358 | B359: Мексика | C359: AndesCargo | D359: AC99462470 | E359: 46288 | F359: In transit | G359: 46295 | H359: =IF(G359="","",Rules!$B$1-G359) | I359: =IF(F359="Address issue","address issue",IF(OR(F359="Delivered",F359="Returned to sender",G359=""),"",IF(AND(Rules!$B$3<>"",F359="Held at customs",H359>=Rules!$B$3),"customs >= "&Rules!$B$3&" days",IF(H359>=Rules!$B$2,"idle >= "&Rules!$B$2&" days","")))) | J359: =IF(I359="","",IF(F359="Address issue",0,COUNTIF($I$2:$I$1001,"address issue"))+COUNTIFS($I$2:$I$1001,"?*",$F$2:$F$1001,IF(F359="Address issue","Address issue","<>Address issue"),$H$2:$H$1001,">"&H359)+1)
A360: 100359 | B360: Канада | C360: PostLink | D360: PL74076129 | E360: 46298 | F360: Label created | G360: 46298 | H360: =IF(G360="","",Rules!$B$1-G360) | I360: =IF(F360="Address issue","address issue",IF(OR(F360="Delivered",F360="Returned to sender",G360=""),"",IF(AND(Rules!$B$3<>"",F360="Held at customs",H360>=Rules!$B$3),"customs >= "&Rules!$B$3&" days",IF(H360>=Rules!$B$2,"idle >= "&Rules!$B$2&" days","")))) | J360: =IF(I360="","",IF(F360="Address issue",0,COUNTIF($I$2:$I$1001,"address issue"))+COUNTIFS($I$2:$I$1001,"?*",$F$2:$F$1001,IF(F360="Address issue","Address issue","<>Address issue"),$H$2:$H$1001,">"&H360)+1)
A361: 100360 | B361: Мексика | C361: SwiftParcel | D361: SP3480269 | E361: 46306 | F361: Delivered | G361: 46310 | H361: =IF(G361="","",Rules!$B$1-G361) | I361: =IF(F361="Address issue","address issue",IF(OR(F361="Delivered",F361="Returned to sender",G361=""),"",IF(AND(Rules!$B$3<>"",F361="Held at customs",H361>=Rules!$B$3),"customs >= "&Rules!$B$3&" days",IF(H361>=Rules!$B$2,"idle >= "&Rules!$B$2&" days","")))) | J361: =IF(I361="","",IF(F361="Address issue",0,COUNTIF($I$2:$I$1001,"address issue"))+COUNTIFS($I$2:$I$1001,"?*",$F$2:$F$1001,IF(F361="Address issue","Address issue","<>Address issue"),$H$2:$H$1001,">"&H361)+1)
A362: 100361 | B362: Бразилія | C362: SwiftParcel | D362: SP5348200 | E362: 46302 | F362: Held at customs | G362: 46308 | H362: =IF(G362="","",Rules!$B$1-G362) | I362: =IF(F362="Address issue","address issue",IF(OR(F362="Delivered",F362="Returned to sender",G362=""),"",IF(AND(Rules!$B$3<>"",F362="Held at customs",H362>=Rules!$B$3),"customs >= "&Rules!$B$3&" days",IF(H362>=Rules!$B$2,"idle >= "&Rules!$B$2&" days","")))) | J362: =IF(I362="","",IF(F362="Address issue",0,COUNTIF($I$2:$I$1001,"address issue"))+COUNTIFS($I$2:$I$1001,"?*",$F$2:$F$1001,IF(F362="Address issue","Address issue","<>Address issue"),$H$2:$H$1001,">"&H362)+1)
A363: 100362 | B363: Мексика | C363: AndesCargo | D363: AC28594317 | E363: 46286 | F363: Delivered | G363: 46293 | H363: =IF(G363="","",Rules!$B$1-G363) | I363: =IF(F363="Address issue","address issue",IF(OR(F363="Delivered",F363="Returned to sender",G363=""),"",IF(AND(Rules!$B$3<>"",F363="Held at customs",H363>=Rules!$B$3),"customs >= "&Rules!$B$3&" days",IF(H363>=Rules!$B$2,"idle >= "&Rules!$B$2&" days","")))) | J363: =IF(I363="","",IF(F363="Address issue",0,COUNTIF($I$2:$I$1001,"address issue"))+COUNTIFS($I$2:$I$1001,"?*",$F$2:$F$1001,IF(F363="Address issue","Address issue","<>Address issue"),$H$2:$H$1001,">"&H363)+1)
A364: 100363 | B364: Бразилія | C364: SwiftParcel | D364: SP8478505 | E364: 46302 | F364: Returned to sender | G364: 46303 | H364: =IF(G364="","",Rules!$B$1-G364) | I364: =IF(F364="Address issue","address issue",IF(OR(F364="Delivered",F364="Returned to sender",G364=""),"",IF(AND(Rules!$B$3<>"",F364="Held at customs",H364>=Rules!$B$3),"customs >= "&Rules!$B$3&" days",IF(H364>=Rules!$B$2,"idle >= "&Rules!$B$2&" days","")))) | J364: =IF(I364="","",IF(F364="Address issue",0,COUNTIF($I$2:$I$1001,"address issue"))+COUNTIFS($I$2:$I$1001,"?*",$F$2:$F$1001,IF(F364="Address issue","Address issue","<>Address issue"),$H$2:$H$1001,">"&H364)+1)
A365: 100364 | B365: Мексика | C365: AndesCargo | D365: AC11965141 | E365: 46305 | F365: In transit | G365: 46308 | H365: =IF(G365="","",Rules!$B$1-G365) | I365: =IF(F365="Address issue","address issue",IF(OR(F365="Delivered",F365="Returned to sender",G365=""),"",IF(AND(Rules!$B$3<>"",F365="Held at customs",H365>=Rules!$B$3),"customs >= "&Rules!$B$3&" days",IF(H365>=Rules!$B$2,"idle >= "&Rules!$B$2&" days","")))) | J365: =IF(I365="","",IF(F365="Address issue",0,COUNTIF($I$2:$I$1001,"address issue"))+COUNTIFS($I$2:$I$1001,"?*",$F$2:$F$1001,IF(F365="Address issue","Address issue","<>Address issue"),$H$2:$H$1001,">"&H365)+1)
A366: 100365 | B366: Канада | C366: PostLink | D366: PL48024979 | E366: 46302 | F366: In transit | G366: 46310 | H366: =IF(G366="","",Rules!$B$1-G366) | I366: =IF(F366="Address issue","address issue",IF(OR(F366="Delivered",F366="Returned to sender",G366=""),"",IF(AND(Rules!$B$3<>"",F366="Held at customs",H366>=Rules!$B$3),"customs >= "&Rules!$B$3&" days",IF(H366>=Rules!$B$2,"idle >= "&Rules!$B$2&" days","")))) | J366: =IF(I366="","",IF(F366="Address issue",0,COUNTIF($I$2:$I$1001,"address issue"))+COUNTIFS($I$2:$I$1001,"?*",$F$2:$F$1001,IF(F366="Address issue","Address issue","<>Address issue"),$H$2:$H$1001,">"&H366)+1)
...
